Workbook

Sheet Cover
A1: Quality of Revenue Workbook: Synthetic B2B SaaS Book
A2: As of July 2026. Prepared by Qiuli Lai.
A4: Purpose | B4: Quality-of-revenue workbook for a B2B SaaS book acquired in Dec 2024: diligence benchmarking at close, underwriting forecast vs actual, and current ARR bridge, retention, concentration, revenue-to-cash, renewals and sensitivity.
A5: Evidence boundary | B5: Customer-level data is synthetic. Its Dec 2023 to Dec 2024 retention was calibrated to SaaS Capital 2025 medians, so agreement in that window is by design. Jan 2025 onward is out of sample.
A6: Units | B6: ARR and revenue in $ millions unless a header states $. ARR = 12 x month-end MRR. Percentages stored as fractions.
A7: Colour legend | B7: Blue = hardcoded data or input; black = formula; green = link to another sheet; yellow fill = key assumption to review.
A8: Checks | B8: ARR_Bridge row 12 and Revenue_to_Cash rows 7 and 15 must read zero. Plan_vs_Actual flags whether each month fell inside the band set at close.
A9: Source code | B9: Generated by src/saas_growth_quality/qor_workbook.py from the SQL marts and cleaned tables.
A11: Sheets
A12: Summary | B12: Headline KPIs, all linked
A13: Inputs | B13: Assumptions and cited benchmarks
A14: Diligence | B14: Dec 2023 to Dec 2024 cohort vs SaaS Capital 2025 on matched cuts
A15: Plan_vs_Actual | B15: Underwriting forecast made at close vs actual, Jan 2025 to Jul 2026
A16: ARR_Bridge | B16: Quarterly ARR roll-forward and growth quality ratios
A17: Retention | B17: 12-month cohort GRR/NRR now (Jul 2025 to Jul 2026); monthly-compounding trap
A18: Concentration | B18: Top-N ARR share, HHI, trend
A19: Revenue_to_Cash | B19: Revenue, invoicing, collections, AR, DSO
A20: Renewals | B20: ARR by renewal quarter and expected non-renewal
A21: Sensitivity | B21: Forward 12-month ARR by GRR and expansion
A22: Customer_ARR | B22: Account-level ARR at July 2026
A23: Monthly_Bridge | B23: Monthly list-MRR bridge from SQL

Sheet Summary
A1: Quality of Revenue Summary
A2: Every value links to a working sheet.
A4: KPI | B4: Value | C4: Reference point | D4: Read
A5: Diligence GRR, Dec 2023 to Dec 2024 | B5: =Diligence!C5 -> 0.9093 | C5: =Diligence!D5 -> 0.91 | D5: vs SaaS Capital 2025 median, same window (calibrated)
A6: Diligence NRR, Dec 2023 to Dec 2024 | B6: =Diligence!F5 -> 1.02701 | C6: =Diligence!G5 -> 1.01 | D6: vs SaaS Capital 2025 median, same window (calibrated)
A7: Underwriting forecast error, last month | B7: =Plan_vs_Actual!B26 -> -0.0096980612 | D7: Base case vs actual list ARR
A8: Months inside the 90% band set at close | B8: =Plan_vs_Actual!B25 -> 1 | D8: Out-of-sample interval check
A9: Closing list ARR, latest quarter ($mm) | B9: =ARR_Bridge!R10 -> 145.3696 | D9: Scale
A10: ARR growth, TTM | B10: =ARR_Bridge!B31 -> 0.18511755 | C10: =Inputs!$B$18 -> 0.25 | D10: vs SaaS Capital median revenue growth (different measure, context only)
A11: 12m cohort GRR, now | B11: =Retention!D5 -> 0.92122 | C11: =Inputs!$B$12 -> 0.91 | D11: vs SaaS Capital 2025 median; Benchmarkit 2026 median is 84%
A12: 12m cohort NRR, now | B12: =Retention!E5 -> 1.03067 | C12: =Inputs!$B$13 -> 1.01 | D12: vs SaaS Capital 2025 median
A13: Expansion share of gross new ARR, TTM | B13: =ARR_Bridge!B32 -> 0.55309076 | C13: =Inputs!$B$17 -> 0.4 | D13: vs Benchmarkit median
A14: Top 10 customers, share of ARR | B14: =Concentration!B8 -> 0.037413567 | D14: Concentration
A15: HHI | B15: =Concentration!B13 -> 9.7458572 | D15: 10,000 / HHI = number of equal-sized customers with the same concentration
A16: Cash conversion, latest quarter | B16: =Revenue_to_Cash!S19 -> 0.9715232 | D16: Cash collected / revenue
A17: DSO, latest quarter (days) | B17: =Revenue_to_Cash!S21 -> 31.885715 | D17: Driven by the one-month terms assumption
A18: Failed collections, % of revenue, latest quarter | B18: =Revenue_to_Cash!S20 -> 0.014353899 | D18: Leakage between billing and cash
A19: Committed ARR renewing in next 12 months ($mm) | B19: =Renewals!$E$16 -> 91.81747 | D19: Renewal exposure
A20: Expected ARR lost in next 12 months ($mm) | B20: =Renewals!$E$22 -> 6.391493 | D20: Historical non-renewal rates applied
A21: Expected ARR lost, % of ARR | B21: =Renewals!$E$23 -> 0.046114222 | D21: Compare with 1 - GRR
A22: Value of 1pt of GRR, annual gross profit ($mm) | B22: =Sensitivity!B13 -> 1.090272 | D22: Uses the gross margin input

Sheet Inputs
A1: Inputs and Benchmarks
A2: Blue cells are inputs; yellow cells are the assumptions most worth challenging.
A4: Assumption | B4: Value | C4: Basis
A5: Gross margin on subscription revenue | B5: 0.75 | C5: Assumption for illustration; replace with the company's subscription gross margin.
A6: Days per quarter | B6: 91.25 | C6: 365 / 4, used for DSO.
A7: Payment terms (months), informational | B7: 1 | C7: Set in revenue_quality.py (PAYMENT_TERMS_MONTHS). The panel has no terms field; one-month terms are an assumption. Editing this cell does not re-time cash.
A10: External benchmarks (calibration inputs before close, checks after close)
A11: Benchmark | B11: Value | C11: Source, window and scope
A12: GRR median, all companies, SaaS Capital 2025 | B12: 0.91 | C12: SaaS Capital 2025 retention benchmarks, >1,000 private B2B SaaS companies >$1M ARR, measured Dec 2023 to Dec 2024. https://www.saas-capital.com/wp-content/uploads/2025/09/RB32WS1-2025-B2B-SaaS-Retention-Benchmarks.pdf
A13: NRR median, all companies, SaaS Capital 2025 | B13: 1.01 | C13: SaaS Capital 2025 retention benchmarks, >1,000 private B2B SaaS companies >$1M ARR, measured Dec 2023 to Dec 2024. https://www.saas-capital.com/wp-content/uploads/2025/09/RB32WS1-2025-B2B-SaaS-Retention-Benchmarks.pdf
A14: GRR median, Benchmarkit 2026 | B14: 0.84 | C14: Benchmarkit 2026 SaaS and AI-native metrics; window, sample and definition not disclosed. https://www.benchmarkit.ai/2026-saas-ai-native-metrics
A15: NRR, usage-based pricing, Benchmarkit 2026 | B15: 1.08 | C15: Same source.
A16: NRR, seat-based pricing, Benchmarkit 2026 | B16: 0.98 | C16: Same source.
A17: Expansion share of net new ARR, median, Benchmarkit 2026 | B17: 0.4 | C17: Same source. Compared here with expansion / (new logo + expansion) ARR; the source's denominator is not stated.
A18: Revenue growth median, equity-backed, 2025 | B18: 0.25 | C18: SaaS Capital 2026 growth benchmarks, all sizes (bootstrapped 20%). https://www.saas-capital.com/research/private-saas-company-growth-rate-benchmarks/
A19: GRR median, bootstrapped, SaaS Capital 2025 | B19: 0.92 | C19: SaaS Capital 2025 retention benchmarks, >1,000 private B2B SaaS companies >$1M ARR, measured Dec 2023 to Dec 2024. https://www.saas-capital.com/wp-content/uploads/2025/09/RB32WS1-2025-B2B-SaaS-Retention-Benchmarks.pdf
A20: NRR median, bootstrapped, SaaS Capital 2025 | B20: 1.04 | C20: SaaS Capital 2025 retention benchmarks, >1,000 private B2B SaaS companies >$1M ARR, measured Dec 2023 to Dec 2024. https://www.saas-capital.com/wp-content/uploads/2025/09/RB32WS1-2025-B2B-SaaS-Retention-Benchmarks.pdf
A21: GRR median, equity-backed, SaaS Capital 2025 | B21: 0.9 | C21: SaaS Capital 2025 retention benchmarks, >1,000 private B2B SaaS companies >$1M ARR, measured Dec 2023 to Dec 2024. https://www.saas-capital.com/wp-content/uploads/2025/09/RB32WS1-2025-B2B-SaaS-Retention-Benchmarks.pdf
A22: NRR median, equity-backed, SaaS Capital 2025 | B22: 1.01 | C22: SaaS Capital 2025 retention benchmarks, >1,000 private B2B SaaS companies >$1M ARR, measured Dec 2023 to Dec 2024. https://www.saas-capital.com/wp-content/uploads/2025/09/RB32WS1-2025-B2B-SaaS-Retention-Benchmarks.pdf
A23: GRR median, bootstrapped $3M-$20M, SaaS Capital 2026 | B23: 0.91 | C23: SaaS Capital, published Apr 2026, calendar 2025 (inferred). https://www.saas-capital.com/blog-posts/benchmarking-metrics-for-bootstrapped-saas-companies/
A24: NRR median, bootstrapped $3M-$20M, SaaS Capital 2026 | B24: 1.03 | C24: Same source.

Sheet Diligence
A1: Diligence Benchmark at Close
A2: Our Dec 2023 to Dec 2024 cohort vs SaaS Capital 2025 medians (same window). Calibration window: agreement is by design.
A4: Cut | B4: Accounts | C4: Our GRR | D4: Benchmark GRR | E4: GRR gap | F4: Our NRR | G4: Benchmark NRR | H4: NRR gap | I4: Note
A5: All private B2B SaaS >$1M ARR | B5: 2462 | C5: 0.9093 | D5: 0.91 | E5: =C5-D5 -> -0.0007 | F5: 1.02701 | G5: 1.01 | H5: =F5-G5 -> 0.01701 | I5: Whole portfolio vs this benchmark group
A6: Bootstrapped | B6: 2462 | C6: 0.9093 | D6: 0.92 | E6: =C6-D6 -> -0.0107 | F6: 1.02701 | G6: 1.04 | H6: =F6-G6 -> -0.01299 | I6: Whole portfolio vs this benchmark group
A7: Equity-backed | B7: 2462 | C7: 0.9093 | D7: 0.9 | E7: =C7-D7 -> 0.0093 | F7: 1.02701 | G7: 1.01 | H7: =F7-G7 -> 0.01701 | I7: Whole portfolio vs this benchmark group
A8: ACV <$12k | B8: 1059 | C8: 0.89175 | D8: 0.9 | E8: =C8-D8 -> -0.00825 | F8: 1.00937 | G8: 0.98 | H8: =F8-G8 -> 0.02937
A9: ACV $12k-$25k | B9: 520 | C9: 0.89621 | D9: 0.91 | E9: =C9-D9 -> -0.01379 | F9: 1.01491 | G9: 1.03 | H9: =F9-G9 -> -0.01509
A10: ACV $25k-$50k | B10: 426 | C10: 0.9118 | D10: 0.91 | E10: =C10-D10 -> 0.0018 | F10: 1.0223 | G10: 1.02 | H10: =F10-G10 -> 0.0023
A11: ACV $50k-$100k | B11: 225 | C11: 0.89704 | D11: 0.9 | E11: =C11-D11 -> -0.00296 | F11: 1.01051 | G11: 1.04 | H11: =F11-G11 -> -0.02949
A12: ACV $100k-$250k | B12: 207 | C12: 0.92882 | D12: 0.91 | E12: =C12-D12 -> 0.01882 | F12: 1.05051 | G12: 1.02 | H12: =F12-G12 -> 0.03051
A13: ACV >$250k | B13: 25 | C13: 0.87573 | D13: 0.95 | E13: =C13-D13 -> -0.07427 | F13: 0.99824 | G13: 1.06 | H13: =F13-G13 -> -0.06176 | I13: Fewer than 30 accounts; not compared
A14: Annual contracts | B14: 1223 | C14: 0.90406 | D14: 0.9 | E14: =C14-D14 -> 0.00406 | F14: 1.04164 | G14: 1.01 | H14: =F14-G14 -> 0.03164
A15: Month-to-month contracts | B15: 783 | C15: 0.90343 | D15: 0.89 | E15: =C15-D15 -> 0.01343 | F15: 1.0272 | G15: 1 | H15: =F15-G15 -> 0.0272
A16: Multi-year contracts | B16: 456 | C16: 0.91616 | D16: 0.94 | E16: =C16-D16 -> -0.02384 | F16: 1.01095 | G16: 1.03 | H16: =F16-G16 -> -0.01905

Sheet Plan_vs_Actual
A1: Underwriting Forecast vs Actual (list ARR, $mm)
A2: Forecast and band set at close from pre-close months only; actuals after close.
A4: Month | B4: Base case | C4: Band low (p05) | D4: Band high (p95) | E4: Actual | F4: Base vs actual | G4: Inside 90% band
A5: 2025-01 | B5: 114.4667 | C5: 113.7983 | D5: 115.1315 | E5: 114.5889 | F5: =IF(E5=0,0,B5/E5-1) -> -0.0010664209 | G5: =IF(AND(E5>=C5,E5<=D5),1,0) -> 1
A6: 2025-02 | B6: 116.1414 | C6: 115.1447 | D6: 117.39 | E6: 115.2292 | F6: =IF(E6=0,0,B6/E6-1) -> 0.0079163962 | G6: =IF(AND(E6>=C6,E6<=D6),1,0) -> 1
A7: 2025-03 | B7: 117.8196 | C7: 116.5645 | D7: 119.292 | E7: 116.5863 | F7: =IF(E7=0,0,B7/E7-1) -> 0.01057843 | G7: =IF(AND(E7>=C7,E7<=D7),1,0) -> 1
A8: 2025-04 | B8: 119.5014 | C8: 118.061 | D8: 121.1988 | E8: 118.0619 | F8: =IF(E8=0,0,B8/E8-1) -> 0.012192757 | G8: =IF(AND(E8>=C8,E8<=D8),1,0) -> 1
A9: 2025-05 | B9: 121.1868 | C9: 119.5365 | D9: 123.0339 | E9: 120.2793 | F9: =IF(E9=0,0,B9/E9-1) -> 0.0075449392 | G9: =IF(AND(E9>=C9,E9<=D9),1,0) -> 1
A10: 2025-06 | B10: 122.8758 | C10: 120.9741 | D10: 124.8937 | E10: 122.6625 | F10: =IF(E10=0,0,B10/E10-1) -> 0.0017389178 | G10: =IF(AND(E10>=C10,E10<=D10),1,0) -> 1
A11: 2025-07 | B11: 124.5684 | C11: 122.5916 | D11: 126.7481 | E11: 124.1838 | F11: =IF(E11=0,0,B11/E11-1) -> 0.0030970223 | G11: =IF(AND(E11>=C11,E11<=D11),1,0) -> 1
A12: 2025-08 | B12: 126.2646 | C12: 124.143 | D12: 128.5992 | E12: 126.1992 | F12: =IF(E12=0,0,B12/E12-1) -> 0.00051822832 | G12: =IF(AND(E12>=C12,E12<=D12),1,0) -> 1
A13: 2025-09 | B13: 127.9645 | C13: 125.6709 | D13: 130.5042 | E13: 128.1118 | F13: =IF(E13=0,0,B13/E13-1) -> -0.001149777 | G13: =IF(AND(E13>=C13,E13<=D13),1,0) -> 1
A14: 2025-10 | B14: 129.668 | C14: 127.2689 | D14: 132.3195 | E14: 130.7919 | F14: =IF(E14=0,0,B14/E14-1) -> -0.0085930398 | G14: =IF(AND(E14>=C14,E14<=D14),1,0) -> 1
A15: 2025-11 | B15: 131.3751 | C15: 128.8476 | D15: 134.2161 | E15: 132.2219 | F15: =IF(E15=0,0,B15/E15-1) -> -0.0064043854 | G15: =IF(AND(E15>=C15,E15<=D15),1,0) -> 1
A16: 2025-12 | B16: 133.0859 | C16: 130.4674 | D16: 136.0352 | E16: 135.2531 | F16: =IF(E16=0,0,B16/E16-1) -> -0.016023293 | G16: =IF(AND(E16>=C16,E16<=D16),1,0) -> 1
... A23: 2026-07 | B23: 145.1644 | C23: 141.6955 | D23: 149.0632 | E23: 146.586 | F23: =IF(E23=0,0,B23/E23-1) -> -0.0096980612 | G23: =IF(AND(E23>=C23,E23<=D23),1,0) -> 1
A25: Months inside the 90% band | B25: =AVERAGE(G5:G23) -> 1
A26: Forecast error at the last month | B26: =F23 -> -0.0096980612
A28: Retention plan (diligence GRR/NRR held flat) vs actual rolling 12-month cohorts
A29: Period end | B29: Plan GRR | C29: Actual GRR | D29: GRR variance | E29: Plan NRR | F29: Actual NRR | G29: NRR variance
A30: 2025-12 | B30: 0.9093 | C30: 0.92543 | D30: =C30-B30 -> 0.01613 | E30: 1.02701 | F30: 1.0318 | G30: =F30-E30 -> 0.00479
A31: 2026-01 | B31: 0.9093 | C31: 0.92535 | D31: =C31-B31 -> 0.01605 | E31: 1.02701 | F31: 1.03226 | G31: =F31-E31 -> 0.00525
A32: 2026-02 | B32: 0.9093 | C32: 0.93091 | D32: =C32-B32 -> 0.02161 | E32: 1.02701 | F32: 1.04273 | G32: =F32-E32 -> 0.01572
A33: 2026-03 | B33: 0.9093 | C33: 0.92858 | D33: =C33-B33 -> 0.01928 | E33: 1.02701 | F33: 1.04175 | G33: =F33-E33 -> 0.01474
A34: 2026-04 | B34: 0.9093 | C34: 0.92875 | D34: =C34-B34 -> 0.01945 | E34: 1.02701 | F34: 1.0391 | G34: =F34-E34 -> 0.01209
A35: 2026-05 | B35: 0.9093 | C35: 0.92613 | D35: =C35-B35 -> 0.01683 | E35: 1.02701 | F35: 1.03793 | G35: =F35-E35 -> 0.01092
A36: 2026-06 | B36: 0.9093 | C36: 0.92572 | D36: =C36-B36 -> 0.01642 | E36: 1.02701 | F36: 1.0381 | G36: =F36-E36 -> 0.01109
A37: 2026-07 | B37: 0.9093 | C37: 0.92122 | D37: =C37-B37 -> 0.01192 | E37: 1.02701 | F37: 1.03067 | G37: =F37-E37 -> 0.00366

Sheet ARR_Bridge
A1: Quarterly ARR Bridge ($mm, list price)
A2: Opening links to the prior quarter's closing; row 12 must be zero.
A4: $mm | B4: 2022Q2 | C4: 2022Q3 | D4: 2022Q4 | E4: 2023Q1 | F4: 2023Q2 | G4: 2023Q3 | H4: 2023Q4 | I4: 2024Q1 | J4: 2024Q2 | K4: 2024Q3 | L4: 2024Q4 | M4: 2025Q1 | N4: 2025Q2 | O4: 2025Q3 | P4: 2025Q4 | Q4: 2026Q1 | R4: 2026Q2
A5: Opening ARR | B5: 60.3637 | C5: =B10 -> 63.6655 | D5: =C10 -> 68.0027 | E5: =D10 -> 73.2332 | F5: =E10 -> 76.9986 | G5: =F10 -> 80.7655 | H5: =G10 -> 86.6753 | I5: =H10 -> 93.0416 | J5: =I10 -> 97.5328 | ... R5: =Q10 -> 140.1706
A6: New logo ARR | B6: 2.9111 | C6: 4.0477 | D6: 5.0081 | E6: 3.1292 | F6: 3.3941 | G6: 5.7866 | H6: 5.3844 | I6: 4.1764 | J6: 4.2339 | K6: 3.8504 | L6: 4.8966 | M6: 4.2988 | N6: 4.3902 | O6: 4.7617 | P6: 5.4746 | Q6: 4.4325 | R6: 3.5596
A7: Expansion ARR | B7: 2.8133 | C7: 2.4724 | D7: 2.8985 | E7: 3.3979 | F7: 3.2561 | G7: 3.4393 | H7: 3.8155 | I7: 3.8609 | J7: 4.5356 | K7: 4.5407 | L7: 4.7012 | M7: 4.44 | N7: 5.0978 | O7: 4.9784 | P7: 5.911 | Q7: 5.8025 | R7: 5.8674
A8: Contraction ARR | B8: -1.0374 | C8: -1.0953 | D8: -1.1894 | E8: -1.3545 | F8: -1.2686 | G8: -1.4894 | H8: -1.4108 | I8: -1.7975 | J8: -1.9285 | K8: -1.8055 | L8: -1.9759 | M8: -2.4845 | N8: -2.0784 | O8: -2.4662 | P8: -2.6481 | Q8: -2.5898 | R8: -2.6335
A9: Churned ARR | B9: -1.3852 | C9: -1.0876 | D9: -1.4867 | E9: -1.4072 | F9: -1.6147 | G9: -1.8267 | H9: -1.4228 | I9: -1.7486 | J9: -1.2044 | K9: -2.1489 | L9: -2.4324 | M9: -2.4636 | N9: -1.3333 | O9: -1.8246 | P9: -1.5962 | Q9: -2.7278 | R9: -1.5945
A10: Closing ARR (roll-forward) | B10: =SUM(B5:B9) -> 63.6655 | C10: =SUM(C5:C9) -> 68.0027 | D10: =SUM(D5:D9) -> 73.2332 | E10: =SUM(E5:E9) -> 76.9986 | F10: =SUM(F5:F9) -> 80.7655 | G10: =SUM(G5:G9) -> 86.6753 | H10: =SUM(H5:H9) -> 93.0416 | I10: =SUM(I5:I9) -> 97.5328 | ... R10: =SUM(R5:R9) -> 145.3696
A11: Closing ARR per SQL mart | B11: 63.6655 | C11: 68.0026 | D11: 73.2332 | E11: 76.9987 | F11: 80.7656 | G11: 86.6754 | H11: 93.0416 | I11: 97.5328 | J11: 103.1694 | K11: 107.6061 | L11: 112.7957 | M11: 116.5863 | N11: 122.6625 | O11: 128.1118 | P11: 135.2531 | Q11: 140.1706 | R11: 145.3696
A12: Check: roll-forward minus mart | B12: =ROUND(B10-B11,3) -> 0 | C12: =ROUND(C10-C11,3) -> 0 | D12: =ROUND(D10-D11,3) -> 0 | E12: =ROUND(E10-E11,3) -> 0 | F12: =ROUND(F10-F11,3) -> 0 | G12: =ROUND(G10-G11,3) -> 0 | H12: =ROUND(H10-H11,3) -> 0 | I12: =ROUND(I10-I11,3) -> 0 | ... R12: =ROUND(R10-R11,3) -> 0
A14: Growth quality ratios
A15: Net new ARR | B15: =B10-B5 -> 3.3018 | C15: =C10-C5 -> 4.3372 | D15: =D10-D5 -> 5.2305 | E15: =E10-E5 -> 3.7654 | F15: =F10-F5 -> 3.7669 | G15: =G10-G5 -> 5.9098 | H15: =H10-H5 -> 6.3663 | I15: =I10-I5 -> 4.4912 | ... R15: =R10-R5 -> 5.199
A16: Gross new ARR (new + expansion) | B16: =B6+B7 -> 5.7244 | C16: =C6+C7 -> 6.5201 | D16: =D6+D7 -> 7.9066 | E16: =E6+E7 -> 6.5271 | F16: =F6+F7 -> 6.6502 | G16: =G6+G7 -> 9.2259 | H16: =H6+H7 -> 9.1999 | I16: =I6+I7 -> 8.0373 | ... R16: =R6+R7 -> 9.427
A17: Expansion share of gross new ARR | B17: =IF(B16=0,0,B7/B16) -> 0.49145762 | C17: =IF(C16=0,0,C7/C16) -> 0.37919664 | D17: =IF(D16=0,0,D7/D16) -> 0.36659247 | E17: =IF(E16=0,0,E7/E16) -> 0.52058341 | F17: =IF(F16=0,0,F7/F16) -> 0.48962437 | G17: =IF(G16=0,0,G7/G16) -> 0.37278748 | H17: =IF(H16=0,0,H7/H16) -> 0.41473277 | I17: =IF(I16=0,0,I7/I16) -> 0.48037276 | ... R17: =IF(R16=0,0,R7/R16) -> 0.62240373
A18: Quarterly gross retention (bridge) | B18: =IF(B5=0,0,1+(B8+B9)/B5) -> 0.95986661 | C18: =IF(C5=0,0,1+(C8+C9)/C5) -> 0.96571298 | D18: =IF(D5=0,0,1+(D8+D9)/D5) -> 0.96064715 | E18: =IF(E5=0,0,1+(E8+E9)/E5) -> 0.96228896 | F18: =IF(F5=0,0,1+(F8+F9)/F5) -> 0.96255386 | G18: =IF(G5=0,0,1+(G8+G9)/G5) -> 0.95894163 | H18: =IF(H5=0,0,1+(H8+H9)/H5) -> 0.96730787 | I18: =IF(I5=0,0,1+(I8+I9)/I5) -> 0.96188694 | ... R18: =IF(R5=0,0,1+(R8+R9)/R5) -> 0.96983676
A19: Quarterly net retention (bridge) | B19: =IF(B5=0,0,1+(B7+B8+B9)/B5) -> 1.0064724 | C19: =IF(C5=0,0,1+(C7+C8+C9)/C5) -> 1.0045472 | D19: =IF(D5=0,0,1+(D7+D8+D9)/D5) -> 1.0032705 | E19: =IF(E5=0,0,1+(E7+E8+E9)/E5) -> 1.0086873 | F19: =IF(F5=0,0,1+(F7+F8+F9)/F5) -> 1.0048416 | G19: =IF(G5=0,0,1+(G7+G8+G9)/G5) -> 1.0015254 | H19: =IF(H5=0,0,1+(H7+H8+H9)/H5) -> 1.0113285 | I19: =IF(I5=0,0,1+(I7+I8+I9)/I5) -> 1.0033834 | ... R19: =IF(R5=0,0,1+(R7+R8+R9)/R5) -> 1.0116957
A20: Quick ratio (gross new / gross losses) | B20: =IF((B8+B9)=0,0,B16/-(B8+B9)) -> 2.3629159 | C20: =IF((C8+C9)=0,0,C16/-(C8+C9)) -> 2.9868982 | D20: =IF((D8+D9)=0,0,D16/-(D8+D9)) -> 2.9545234 | E20: =IF((E8+E9)=0,0,E16/-(E8+E9)) -> 2.3634356 | F20: =IF((F8+F9)=0,0,F16/-(F8+F9)) -> 2.3064544 | G20: =IF((G8+G9)=0,0,G16/-(G8+G9)) -> 2.7821537 | H20: =IF((H8+H9)=0,0,H16/-(H8+H9)) -> 3.246718 | I20: =IF((I8+I9)=0,0,I16/-(I8+I9)) -> 2.2665181 | ... R20: =IF((R8+R9)=0,0,R16/-(R8+R9)) -> 2.2296594
A21: ARR growth, QoQ | B21: =IF(B5=0,0,B10/B5-1) -> 0.054698436 | C21: =IF(C5=0,0,C10/C5-1) -> 0.068124809 | D21: =IF(D5=0,0,D10/D5-1) -> 0.076916064 | E21: =IF(E5=0,0,E10/E5-1) -> 0.051416571 | F21: =IF(F5=0,0,F10/F5-1) -> 0.048921669 | G21: =IF(G5=0,0,G10/G5-1) -> 0.073172332 | H21: =IF(H5=0,0,H10/H5-1) -> 0.073449991 | I21: =IF(I5=0,0,I10/I5-1) -> 0.048270881 | ... R21: =IF(R5=0,0,R10/R5-1) -> 0.037090517
A22: ARR growth, YoY | F22: =IF(B10=0,0,F10/B10-1) -> 0.26859131 | G22: =IF(C10=0,0,G10/C10-1) -> 0.27458616 | H22: =IF(D10=0,0,H10/D10-1) -> 0.27048388 | I22: =IF(E10=0,0,I10/E10-1) -> 0.26668277 | J22: =IF(F10=0,0,J10/F10-1) -> 0.27739443 | K22: =IF(G10=0,0,K10/G10-1) -> 0.24148518 | L22: =IF(H10=0,0,L10/H10-1) -> 0.21231363 | M22: =IF(I10=0,0,M10/I10-1) -> 0.19535479 | ... R22: =IF(N10=0,0,R10/N10-1) -> 0.18511755
A24: Trailing four quarters
A25: Metric | B25: TTM | C25: Benchmark | D25: Variance
A26: Opening ARR four quarters ago | B26: =O5 -> 122.6626
A27: New logo ARR | B27: =SUM(O6:R6) -> 18.2284
A28: Expansion ARR | B28: =SUM(O7:R7) -> 22.5593
A29: Contraction + churn ARR | B29: =SUM(O8:R9) -> -18.0807
A30: Closing ARR | B30: =R10 -> 145.3696
A31: ARR growth, TTM | B31: =IF(B26=0,0,B30/B26-1) -> 0.18511755 | C31: =Inputs!$B$18 -> 0.25 | D31: =B31-C31 -> -0.06488245
A32: Expansion share of gross new ARR, TTM | B32: =IF((B27+B28)=0,0,B28/(B27+B28)) -> 0.55309076 | C32: =Inputs!$B$17 -> 0.4 | D32: =B32-C32 -> 0.15309076
A33: Gross loss rate on opening ARR (bridge, includes in-year cohorts) | B33: =IF(B26=0,0,-B29/B26) -> 0.1474019
A35: The bridge loss rate is not GRR: it includes losses from customers acquired during the year. Cohort GRR is on the Retention sheet.

Sheet Retention
A1: 12-Month Cohort Retention (list MRR)
A2: Accounts active at Jul 2025, measured at Jul 2026. Groups under 30 accounts suppressed.
A4: Cohort | B4: Accounts | C4: Start ARR ($mm) | D4: 12m GRR | E4: 12m NRR | F4: Logo churn | G4: GRR vs SaaS Capital | H4: GRR vs Benchmarkit | I4: NRR vs SaaS Capital
A5: Portfolio | B5: 3077 | C5: 124.1838 | D5: 0.92122 | E5: 1.03067 | F5: 0.08677 | G5: =D5-Inputs!$B$12 -> 0.01122 | H5: =D5-Inputs!$B$14 -> 0.08122 | I5: =E5-Inputs!$B$13 -> 0.02067
A6: segment: Enterprise | B6: 352 | C6: 63.4782 | D6: 0.93587 | E6: 1.04209 | F6: 0.04545 | G6: =D6-Inputs!$B$12 -> 0.02587 | H6: =D6-Inputs!$B$14 -> 0.09587 | I6: =E6-Inputs!$B$13 -> 0.03209
A7: segment: Mid-Market | B7: 939 | C7: 41.4573 | D7: 0.91544 | E7: 1.02895 | F7: 0.07242 | G7: =D7-Inputs!$B$12 -> 0.00544 | H7: =D7-Inputs!$B$14 -> 0.07544 | I7: =E7-Inputs!$B$13 -> 0.01895
A8: segment: SMB | B8: 1786 | C8: 19.2482 | D8: 0.88534 | E8: 0.99672 | F8: 0.10246 | G8: =D8-Inputs!$B$12 -> -0.02466 | H8: =D8-Inputs!$B$14 -> 0.04534 | I8: =E8-Inputs!$B$13 -> -0.01328
A9: pricing model: hybrid | B9: 794 | C9: 41.0521 | D9: 0.92894 | E9: 1.0363 | F9: 0.07557 | G9: =D9-Inputs!$B$12 -> 0.01894 | H9: =D9-Inputs!$B$14 -> 0.08894 | I9: =E9-Inputs!$B$13 -> 0.0263
A10: pricing model: seat | B10: 1718 | C10: 51.4476 | D10: 0.92306 | E10: 1.01095 | F10: 0.09779 | G10: =D10-Inputs!$B$12 -> 0.01306 | H10: =D10-Inputs!$B$14 -> 0.08306 | I10: =E10-Inputs!$B$13 -> 0.00095
A11: pricing model: usage | B11: 565 | C11: 31.6841 | D11: 0.90822 | E11: 1.0554 | F11: 0.06903 | G11: =D11-Inputs!$B$12 -> -0.00178 | H11: =D11-Inputs!$B$14 -> 0.06822 | I11: =E11-Inputs!$B$13 -> 0.0454
A12: contract term months: 1 | B12: 1004 | C12: 10.9613 | D12: 0.89574 | E12: 1.00859 | F12: 0.09263 | G12: =D12-Inputs!$B$12 -> -0.01426 | H12: =D12-Inputs!$B$14 -> 0.05574 | I12: =E12-Inputs!$B$13 -> -0.00141
A13: contract term months: 12 | B13: 1504 | C13: 60.5273 | D13: 0.92096 | E13: 1.04701 | F13: 0.09774 | G13: =D13-Inputs!$B$12 -> 0.01096 | H13: =D13-Inputs!$B$14 -> 0.08096 | I13: =E13-Inputs!$B$13 -> 0.03701
A14: contract term months: 24 | B14: 469 | C14: 36.7818 | D14: 0.93562 | E14: 1.02925 | F14: 0.04478 | G14: =D14-Inputs!$B$12 -> 0.02562 | H14: =D14-Inputs!$B$14 -> 0.09562 | I14: =E14-Inputs!$B$13 -> 0.01925
A15: contract term months: 36 | B15: 100 | C15: 15.9134 | D15: 0.90645 | E15: 0.98703 | F15: 0.06 | G15: =D15-Inputs!$B$12 -> -0.00355 | H15: =D15-Inputs!$B$14 -> 0.06645 | I15: =E15-Inputs!$B$13 -> -0.02297
A16: channel: Inbound | B16: 809 | C16: 30.0476 | D16: 0.91544 | E16: 1.03029 | F16: 0.09023 | G16: =D16-Inputs!$B$12 -> 0.00544 | H16: =D16-Inputs!$B$14 -> 0.07544 | I16: =E16-Inputs!$B$13 -> 0.02029
... A27: industry: Retail | B27: 422 | C27: 18.9507 | D27: 0.91569 | E27: 1.03925 | F27: 0.09479 | G27: =D27-Inputs!$B$12 -> 0.00569 | H27: =D27-Inputs!$B$14 -> 0.07569 | I27: =E27-Inputs!$B$13 -> 0.02925
A29: Usage minus seat NRR (pp) | B29: =E11-E10 -> 0.04445 | C29: =Inputs!$B$15-Inputs!$B$16 -> 0.1 | D29: Benchmarkit 2026 gap in column C
A31: Definition trap: monthly retention compounded vs 12-month cohort
A32: Measure | B32: Value
A33: Average monthly GRR, last 12 months (Monthly_Bridge) | B33: =AVERAGE(Monthly_Bridge!I47:I58) -> 0.98836624
A34: Average monthly NRR, last 12 months | B34: =AVERAGE(Monthly_Bridge!J47:J58) -> 1.0022486
A35: Monthly GRR compounded to 12 months | B35: =B33^12 -> 0.86899015
A36: Monthly NRR compounded to 12 months | B36: =B34^12 -> 1.0273199
A37: 12-month cohort GRR (row 5) | B37: =D5 -> 0.92122
A38: 12-month cohort NRR (row 5) | B38: =E5 -> 1.03067
A40: Compounded monthly GRR sits well below cohort GRR. Two mechanisms are likely, not decomposed here: each monthly usage dip is booked as contraction and the recovery as expansion, and the monthly base includes in-year new logos, which churn more. A monthly GRR near 99% must not be compared with an annual benchmark.

Sheet Concentration
A1: Customer Concentration (billed ARR, July 2026)
A2: All formulas read Customer_ARR; HHI on a 0 to 10,000 scale.
A4: Metric | B4: Value
A5: Active customers | B5: =COUNT(Customer_ARR!$I$5:$I$3509) -> 3505
A6: Total billed ARR ($) | B6: =SUM(Customer_ARR!$I$5:$I$3509) -> 1.3860136e+08
A7: Largest customer share | B7: =LARGE(Customer_ARR!$I$5:$I$3509,1)/B6 -> 0.0060172318
A8: Top 10 share | B8: =SUMPRODUCT(LARGE(Customer_ARR!$I$5:$I$3509,ROW($1:$10)))/B6 -> 0.037413567
A9: Top 20 share | B9: =SUMPRODUCT(LARGE(Customer_ARR!$I$5:$I$3509,ROW($1:$20)))/B6 -> 0.063860602
A10: Top 50 share | B10: =SUMPRODUCT(LARGE(Customer_ARR!$I$5:$I$3509,ROW($1:$50)))/B6 -> 0.13060803
A11: Top 10% of customers, count | B11: =ROUNDUP(0.1*B5,0) -> 351
A12: Top 10% of customers, ARR share (list sorted descending) | B12: =SUM(Customer_ARR!$I$5:INDEX(Customer_ARR!$I:$I,4+B11))/B6 -> 0.48556207
A13: HHI | B13: =SUMPRODUCT((Customer_ARR!$I$5:$I$3509/B6)^2)*10000 -> 9.7458572
A14: Equivalent number of equal-sized customers (10,000 / HHI) | B14: =IF(B13=0,0,10000/B13) -> 1026.077
A16: A single-account share this low is a property of the simulated size distribution; in real diligence concentration is often the first red flag, so the test matters more than this result.
A17: ARR by segment
A18: Segment | B18: Customers | C18: Billed ARR ($) | D18: Share
A19: Enterprise | B19: =COUNTIFS(Customer_ARR!$B$5:$B$3509,A19) -> 391 | C19: =SUMIFS(Customer_ARR!$I$5:$I$3509,Customer_ARR!$B$5:$B$3509,A19) -> 69102028 | D19: =C19/$B$6 -> 0.49856674
A20: Mid-Market | B20: =COUNTIFS(Customer_ARR!$B$5:$B$3509,A20) -> 1095 | C20: =SUMIFS(Customer_ARR!$I$5:$I$3509,Customer_ARR!$B$5:$B$3509,A20) -> 47736124 | D20: =C20/$B$6 -> 0.3444131
A21: SMB | B21: =COUNTIFS(Customer_ARR!$B$5:$B$3509,A21) -> 2019 | C21: =SUMIFS(Customer_ARR!$I$5:$I$3509,Customer_ARR!$B$5:$B$3509,A21) -> 21763209 | D21: =C21/$B$6 -> 0.15702016
A23: Top 20 customers
A24: Customer | B24: Segment | C24: Industry | D24: Billed ARR ($) | E24: Share | F24: Cumulative | G24: Months to renewal | H24: Discount
A25: =Customer_ARR!A5 -> C00873 | B25: =Customer_ARR!B5 -> Enterprise | C25: =Customer_ARR!C5 -> Education | D25: =Customer_ARR!I5 -> 833996.52 | E25: =D25/$B$6 -> 0.0060172318 | F25: =E25 -> 0.0060172318 | G25: =Customer_ARR!H5 -> 14 | H25: =Customer_ARR!G5 -> 0
A26: =Customer_ARR!A6 -> C00435 | B26: =Customer_ARR!B6 -> Enterprise | C26: =Customer_ARR!C6 -> Retail | D26: =Customer_ARR!I6 -> 541124.64 | E26: =D26/$B$6 -> 0.0039041798 | F26: =F25+E26 -> 0.0099214116 | G26: =Customer_ARR!H6 -> 8 | H26: =Customer_ARR!G6 -> 0
A27: =Customer_ARR!A7 -> C00720 | B27: =Customer_ARR!B7 -> Enterprise | C27: =Customer_ARR!C7 -> Manufacturing | D27: =Customer_ARR!I7 -> 521289.24 | E27: =D27/$B$6 -> 0.0037610687 | F27: =F26+E27 -> 0.01368248 | G27: =Customer_ARR!H7 -> 20 | H27: =Customer_ARR!G7 -> 0.25
A28: =Customer_ARR!A8 -> C00127 | B28: =Customer_ARR!B8 -> Enterprise | C28: =Customer_ARR!C8 -> Education | D28: =Customer_ARR!I8 -> 510670.56 | E28: =D28/$B$6 -> 0.0036844556 | F28: =F27+E28 -> 0.017366936 | G28: =Customer_ARR!H8 -> 12 | H28: =Customer_ARR!G8 -> 0.05
A29: =Customer_ARR!A9 -> C01662 | B29: =Customer_ARR!B9 -> Enterprise | C29: =Customer_ARR!C9 -> Unknown | D29: =Customer_ARR!I9 -> 503840.88 | E29: =D29/$B$6 -> 0.0036351799 | F29: =F28+E29 -> 0.021002116 | G29: =Customer_ARR!H9 -> 18 | H29: =Customer_ARR!G9 -> 0
A30: =Customer_ARR!A10 -> C02577 | B30: =Customer_ARR!B10 -> Enterprise | C30: =Customer_ARR!C10 -> Education | D30: =Customer_ARR!I10 -> 499972.92 | E30: =D30/$B$6 -> 0.0036072728 | F30: =F29+E30 -> 0.024609389 | G30: =Customer_ARR!H10 -> 1 | H30: =Customer_ARR!G10 -> 0
A31: =Customer_ARR!A11 -> C00911 | B31: =Customer_ARR!B11 -> Enterprise | C31: =Customer_ARR!C11 -> Retail | D31: =Customer_ARR!I11 -> 491146.08 | E31: =D31/$B$6 -> 0.0035435877 | F31: =F30+E31 -> 0.028152976 | G31: =Customer_ARR!H11 -> 19 | H31: =Customer_ARR!G11 -> 0
A32: =Customer_ARR!A12 -> C02271 | B32: =Customer_ARR!B12 -> Enterprise | C32: =Customer_ARR!C12 -> Logistics | D32: =Customer_ARR!I12 -> 436212 | E32: =D32/$B$6 -> 0.0031472418 | F32: =F31+E32 -> 0.031300218 | G32: =Customer_ARR!H12 -> 6 | H32: =Customer_ARR!G12 -> 0
A33: =Customer_ARR!A13 -> C01211 | B33: =Customer_ARR!B13 -> Enterprise | C33: =Customer_ARR!C13 -> Manufacturing | D33: =Customer_ARR!I13 -> 428389.92 | E33: =D33/$B$6 -> 0.003090806 | F33: =F32+E33 -> 0.034391024 | G33: =Customer_ARR!H13 -> 4 | H33: =Customer_ARR!G13 -> 0
A34: =Customer_ARR!A14 -> C02178 | B34: =Customer_ARR!B14 -> Enterprise | C34: =Customer_ARR!C14 -> Retail | D34: =Customer_ARR!I14 -> 418928.52 | E34: =D34/$B$6 -> 0.0030225426 | F34: =F33+E34 -> 0.037413567 | G34: =Customer_ARR!H14 -> 4 | H34: =Customer_ARR!G14 -> 0
A35: =Customer_ARR!A15 -> C00416 | B35: =Customer_ARR!B15 -> Enterprise | C35: =Customer_ARR!C15 -> Fintech | D35: =Customer_ARR!I15 -> 409185.96 | E35: =D35/$B$6 -> 0.0029522507 | F35: =F34+E35 -> 0.040365817 | G35: =Customer_ARR!H15 -> 21 | H35: =Customer_ARR!G15 -> 0
A36: =Customer_ARR!A16 -> C01234 | B36: =Customer_ARR!B16 -> Enterprise | C36: =Customer_ARR!C16 -> Healthcare | D36: =Customer_ARR!I16 -> 407590.8 | E36: =D36/$B$6 -> 0.0029407417 | F36: =F35+E36 -> 0.043306559 | G36: =Customer_ARR!H16 -> 3 | H36: =Customer_ARR!G16 -> 0
A37: =Customer_ARR!A17 -> C01591 | B37: =Customer_ARR!B17 -> Enterprise | C37: =Customer_ARR!C17 -> Cybersecurity | D37: =Customer_ARR!I17 -> 382728.84 | E37: =D37/$B$6 -> 0.0027613642 | F37: =F36+E37 -> 0.046067923 | G37: =Customer_ARR!H17 -> 8 | H37: =Customer_ARR!G17 -> 0
... A44: =Customer_ARR!A24 -> C00480 | B44: =Customer_ARR!B24 -> Enterprise | C44: =Customer_ARR!C24 -> Cybersecurity | D44: =Customer_ARR!I24 -> 339431.04 | E44: =D44/$B$6 -> 0.0024489733 | F44: =F43+E44 -> 0.063860602 | G44: =Customer_ARR!H24 -> 24 | H44: =Customer_ARR!G24 -> 0
A47: Concentration trend (quarter-end months)
A48: Month | B48: Customers | C48: Top 10 share | D48: Top 10% of customers share | E48: HHI
A49: 2022-03-01 | B49: 1771 | C49: 0.04551 | D49: 0.47768 | E49: 17.028
A50: 2022-06-01 | B50: 1842 | C50: 0.04621 | D50: 0.4796 | E50: 16.627
A51: 2022-09-01 | B51: 1951 | C51: 0.04619 | D51: 0.47978 | E51: 15.872
...

Sheet Revenue_to_Cash
A1: Revenue, Invoicing and Collections ($mm)
A2: Monthly billing; cash dated at invoice + one month + days late; failed invoices never collected.
A4: $mm | B4: 2022Q1 | C4: 2022Q2 | D4: 2022Q3 | E4: 2022Q4 | F4: 2023Q1 | G4: 2023Q2 | H4: 2023Q3 | I4: 2023Q4 | J4: 2024Q1 | K4: 2024Q2 | L4: 2024Q3 | M4: 2024Q4 | N4: 2025Q1 | O4: 2025Q2 | P4: 2025Q3 | Q4: 2025Q4 | R4: 2026Q1 | S4: 2026Q2
A5: Recognized revenue | B5: 13.90075 | C5: 14.74024 | D5: 15.63973 | E5: 16.92502 | F5: 17.86145 | G5: 18.75602 | H5: 20.00424 | I5: 21.36279 | J5: 22.57843 | K5: 23.86437 | L5: 24.99978 | M5: 26.16732 | N5: 27.24909 | O5: 28.40488 | P5: 29.81261 | Q5: 31.35828 | R5: 32.76953 | S5: 33.85352
A6: Invoiced | B6: 13.90075 | C6: 14.74024 | D6: 15.63973 | E6: 16.92502 | F6: 17.86145 | G6: 18.75602 | H6: 20.00424 | I6: 21.36279 | J6: 22.57843 | K6: 23.86437 | L6: 24.99978 | M6: 26.16732 | N6: 27.24909 | O6: 28.40488 | P6: 29.81261 | Q6: 31.35828 | R6: 32.76953 | S6: 33.85352
A7: Check: invoiced minus revenue | B7: =ROUND(B6-B5,4) -> 0 | C7: =ROUND(C6-C5,4) -> 0 | D7: =ROUND(D6-D5,4) -> 0 | E7: =ROUND(E6-E5,4) -> 0 | F7: =ROUND(F6-F5,4) -> 0 | G7: =ROUND(G6-G5,4) -> 0 | H7: =ROUND(H6-H5,4) -> 0 | I7: =ROUND(I6-I5,4) -> 0 | ... S7: =ROUND(S6-S5,4) -> 0
A8: Failed, never collected | B8: 0.18947 | C8: 0.24323 | D8: 0.36636 | E8: 0.27225 | F8: 0.36806 | G8: 0.26369 | H8: 0.34105 | I8: 0.32423 | J8: 0.35606 | K8: 0.45351 | L8: 0.38429 | M8: 0.47252 | N8: 0.50173 | O8: 0.36897 | P8: 0.57284 | Q8: 0.54826 | R8: 0.48043 | S8: 0.48593
A9: Collectible invoices | B9: =B6-B8 -> 13.71128 | C9: =C6-C8 -> 14.49701 | D9: =D6-D8 -> 15.27337 | E9: =E6-E8 -> 16.65277 | F9: =F6-F8 -> 17.49339 | G9: =G6-G8 -> 18.49233 | H9: =H6-H8 -> 19.66319 | I9: =I6-I8 -> 21.03856 | ... S9: =S6-S8 -> 33.36759
A10: Cash collected | B10: 8.81008 | C10: 14.25494 | D10: 14.91504 | E10: 16.21092 | F10: 17.28637 | G10: 17.99606 | H10: 19.28339 | I10: 20.57197 | J10: 21.84902 | K10: 22.93335 | L10: 24.08676 | M10: 25.37846 | N10: 26.49436 | O10: 27.4003 | P10: 28.8642 | Q10: 30.32542 | R10: 31.8755 | S10: 32.88948
A11: Opening receivables | B11: 0 | C11: =B13 -> 4.90121 | D11: =C13 -> 5.14327 | E11: =D13 -> 5.5016 | F11: =E13 -> 5.94345 | G11: =F13 -> 6.15047 | H11: =G13 -> 6.64673 | I11: =H13 -> 7.02653 | J11: =I13 -> 7.49312 | ... S11: =R13 -> 11.35141
A12: Closing receivables (roll-forward) | B12: =B11+B9-B10 -> 4.9012 | C12: =C11+C9-C10 -> 5.14328 | D12: =D11+D9-D10 -> 5.5016 | E12: =E11+E9-E10 -> 5.94345 | F12: =F11+F9-F10 -> 6.15047 | G12: =G11+G9-G10 -> 6.64674 | H12: =H11+H9-H10 -> 7.02653 | I12: =I11+I9-I10 -> 7.49312 | ... S12: =S11+S9-S10 -> 11.82952
A13: Closing receivables per ledger | B13: 4.90121 | C13: 5.14327 | D13: 5.5016 | E13: 5.94345 | F13: 6.15047 | G13: 6.64673 | H13: 7.02653 | I13: 7.49312 | J13: 7.86647 | K13: 8.34398 | L13: 8.87271 | M13: 9.18905 | N13: 9.44205 | O13: 10.07765 | P13: 10.45322 | Q13: 10.93782 | R13: 11.35141 | S13: 11.82952
A15: Check: roll-forward minus ledger | B15: =ROUND(B12-B13,3) -> 0 | C15: =ROUND(C12-C13,3) -> 0 | D15: =ROUND(D12-D13,3) -> 0 | E15: =ROUND(E12-E13,3) -> 0 | F15: =ROUND(F12-F13,3) -> 0 | G15: =ROUND(G12-G13,3) -> 0 | H15: =ROUND(H12-H13,3) -> 0 | I15: =ROUND(I12-I13,3) -> 0 | ... S15: =ROUND(S12-S13,3) -> 0
A17: Ending billed ARR | B17: 56.90452 | C17: 59.99367 | D17: 64.00104 | E17: 68.89965 | F17: 72.51914 | G17: 76.03604 | H17: 81.6163 | I17: 87.57277 | J17: 91.8261 | K17: 97.13267 | L17: 101.40535 | M17: 106.48112 | N17: 110.05812 | O17: 115.82286 | P17: 121.09757 | Q17: 127.86989 | R17: 132.51876 | S17: 137.41335
A19: Cash conversion (cash / revenue) | B19: =IF(B5=0,0,B10/B5) -> 0.63378451 | C19: =IF(C5=0,0,C10/C5) -> 0.96707652 | D19: =IF(D5=0,0,D10/D5) -> 0.95366352 | E19: =IF(E5=0,0,E10/E5) -> 0.95780803 | F19: =IF(F5=0,0,F10/F5) -> 0.96780329 | G19: =IF(G5=0,0,G10/G5) -> 0.95948181 | H19: =IF(H5=0,0,H10/H5) -> 0.96396514 | I19: =IF(I5=0,0,I10/I5) -> 0.96298143 | ... S19: =IF(S5=0,0,S10/S5) -> 0.9715232
A20: Failed collections, % of revenue | B20: =IF(B5=0,0,B8/B5) -> 0.0136302 | C20: =IF(C5=0,0,C8/C5) -> 0.016501088 | D20: =IF(D5=0,0,D8/D5) -> 0.023424957 | E20: =IF(E5=0,0,E8/E5) -> 0.016085653 | F20: =IF(F5=0,0,F8/F5) -> 0.02060639 | G20: =IF(G5=0,0,G8/G5) -> 0.014058953 | H20: =IF(H5=0,0,H8/H5) -> 0.017048886 | I20: =IF(I5=0,0,I8/I5) -> 0.015177325 | ... S20: =IF(S5=0,0,S8/S5) -> 0.014353899
A21: DSO (days) | B21: =IF(B5=0,0,B13/B5*Inputs!$B$6) -> 32.173474 | C21: =IF(C5=0,0,C13/C5*Inputs!$B$6) -> 31.839603 | D21: =IF(D5=0,0,D13/D5*Inputs!$B$6) -> 32.099084 | E21: =IF(E5=0,0,E13/E5*Inputs!$B$6) -> 32.043673 | F21: =IF(F5=0,0,F13/F5*Inputs!$B$6) -> 31.421323 | G21: =IF(G5=0,0,G13/G5*Inputs!$B$6) -> 32.337037 | H21: =IF(H5=0,0,H13/H5*Inputs!$B$6) -> 32.051748 | I21: =IF(I5=0,0,I13/I5*Inputs!$B$6) -> 32.006456 | ... S21: =IF(S5=0,0,S13/S5*Inputs!$B$6) -> 31.885715
A22: Run-rate conversion (revenue x 4 / ending ARR) | B22: =IF(B17=0,0,B5*4/B17) -> 0.977128 | C22: =IF(C17=0,0,C5*4/C17) -> 0.98278635 | D22: =IF(D17=0,0,D5*4/D17) -> 0.97746724 | E22: =IF(E17=0,0,E5*4/E17) -> 0.98258961 | F22: =IF(F17=0,0,F5*4/F17) -> 0.98519922 | G22: =IF(G17=0,0,G5*4/G17) -> 0.98669105 | H22: =IF(H17=0,0,H5*4/H17) -> 0.98040416 | I22: =IF(I17=0,0,I5*4/I17) -> 0.97577318 | ... S22: =IF(S17=0,0,S5*4/S17) -> 0.98545069
A24: The first quarter's opening receivables are zero because no invoices exist before January 2023.
A25: Every account is billed monthly, so deferred revenue is zero by construction; with annual upfront billing a deferred-revenue line would sit between ARR and cash.

Sheet Renewals
A1: ARR by Renewal Window ($mm, billed, July 2026)
A2: Committed contracts by the quarter they renew; monthly contracts can leave any month.
A4: Renewal window | B4: Enterprise | C4: Mid-Market | D4: SMB | E4: Total
A5: 2026Q3 (Aug to Sep) | B5: 6.19261 | C5: 6.33926 | D5: 1.75862 | E5: =SUM(B5:D5) -> 14.29049
A6: 2026Q4 | B6: 12.23456 | C6: 9.97765 | D6: 2.27164 | E6: =SUM(B6:D6) -> 24.48385
A7: 2027Q1 | B7: 10.30539 | C7: 10.46419 | D7: 2.26513 | E7: =SUM(B7:D7) -> 23.03471
A8: 2027Q2 | B8: 11.67504 | C8: 8.91362 | D8: 2.23064 | E8: =SUM(B8:D8) -> 22.8193
A9: 2027Q3 (Jul only) | B9: 3.80455 | C9: 2.67881 | D9: 0.70576 | E9: =SUM(B9:D9) -> 7.18912
A10: Beyond 12 months | B10: 24.88987 | C10: 9.36258 | D10: 0 | E10: =SUM(B10:D10) -> 34.25245
A11: Monthly (any month) | B11: 0 | C11: 0 | D11: 12.53142 | E11: =SUM(B11:D11) -> 12.53142
A12: Total billed ARR | B12: =SUM(B5:B11) -> 69.10202 | C12: =SUM(C5:C11) -> 47.73611 | D12: =SUM(D5:D11) -> 21.76321 | E12: =SUM(E5:E11) -> 138.60134
A14: Expected ARR not renewed, next 12 months
A15: Line | B15: Enterprise | C15: Mid-Market | D15: SMB | E15: Total
A16: Committed ARR renewing in next 12 months | B16: =SUM(B5:B9) -> 44.21215 | C16: =SUM(C5:C9) -> 38.37353 | D16: =SUM(D5:D9) -> 9.23179 | E16: =SUM(B16:D16) -> 91.81747
A17: Non-renewal rate, contracts ending Aug 2025 to Jun 2026 | B17: 0.03535 | C17: 0.06686 | D17: 0.1036
A18: Expected committed ARR not renewed | B18: =B16*B17 -> 1.5628995 | C18: =C16*C17 -> 2.5656542 | D18: =D16*D17 -> 0.95641344 | E18: =SUM(B18:D18) -> 5.0849672
A19: Monthly-contract ARR | B19: =B11 -> 0 | C19: =C11 -> 0 | D19: =D11 -> 12.53142 | E19: =SUM(B19:D19) -> 12.53142
A20: 12-month gross loss rate, monthly contracts (1 - GRR) | B20: =1-Retention!$D$12 -> 0.10426 | C20: =1-Retention!$D$12 -> 0.10426 | D20: =1-Retention!$D$12 -> 0.10426
A21: Expected monthly-contract ARR lost | B21: =B19*B20 -> 0 | C21: =C19*C20 -> 0 | D21: =D19*D20 -> 1.3065258 | E21: =SUM(B21:D21) -> 1.3065258
A22: Total expected ARR lost, 12 months | B22: =B18+B21 -> 1.5628995 | C22: =C18+C21 -> 2.5656542 | D22: =D18+D21 -> 2.2629393 | E22: =SUM(B22:D22) -> 6.391493
A23: As % of total billed ARR | B23: =IF(B12=0,0,B22/B12) -> 0.022617277 | C23: =IF(C12=0,0,C22/C12) -> 0.053746613 | D23: =IF(D12=0,0,D22/D12) -> 0.10398003 | E23: =E22/E12 -> 0.046114222
A25: Ignores contraction at renewal and early termination, so it understates gross loss; compare with 1 - portfolio GRR on the Retention sheet.

Sheet Sensitivity
A1: Forward 12-Month ARR Sensitivity ($mm, list price)
A2: Ending ARR = opening ARR x (GRR + expansion rate) + new logo ARR. Rows vary GRR, columns vary expansion.
A4: Driver | B4: Value | C4: Source
A5: Opening ARR (latest quarter close) | B5: =ARR_Bridge!R10 -> 145.3696 | C5: ARR_Bridge
A6: Base 12m GRR (portfolio cohort) | B6: =Retention!D5 -> 0.92122 | C6: Retention
A7: Base expansion rate (NRR - GRR) | B7: =Retention!E5-Retention!D5 -> 0.10945 | C7: Retention
A8: New logo ARR, TTM | B8: =ARR_Bridge!B27 -> 18.2284 | C8: ARR_Bridge
A9: Gross margin | B9: =Inputs!$B$5 -> 0.75 | C9: Inputs
A10: Base-case ending ARR | B10: =B5*(B6+B7)+B8 -> 168.05649 | C10: Formula
A11: Base-case ARR growth | B11: =B10/B5-1 -> 0.15606348 | C11: Formula
A12: Value of 1pt of GRR: ARR ($mm) | B12: =B5*0.01 -> 1.453696 | C12: Formula
A13: Value of 1pt of GRR: annual gross profit ($mm) | B13: =B12*B9 -> 1.090272 | C13: Formula
A16: Ending ARR ($mm): GRR (rows) x expansion rate (columns)
A17: GRR \ expansion | B17: =$B$7+(-0.04) -> 0.06945 | C17: =$B$7+(-0.02) -> 0.08945 | D17: =$B$7+(0) -> 0.10945 | E17: =$B$7+(0.02) -> 0.12945 | F17: =$B$7+(0.04) -> 0.14945
A18: 0.84 | B18: =$B$5*($A18+B$17)+$B$8 -> 150.43478 | C18: =$B$5*($A18+C$17)+$B$8 -> 153.34217 | D18: =$B$5*($A18+D$17)+$B$8 -> 156.24957 | E18: =$B$5*($A18+E$17)+$B$8 -> 159.15696 | F18: =$B$5*($A18+F$17)+$B$8 -> 162.06435
A19: 0.86 | B19: =$B$5*($A19+B$17)+$B$8 -> 153.34217 | C19: =$B$5*($A19+C$17)+$B$8 -> 156.24957 | D19: =$B$5*($A19+D$17)+$B$8 -> 159.15696 | E19: =$B$5*($A19+E$17)+$B$8 -> 162.06435 | F19: =$B$5*($A19+F$17)+$B$8 -> 164.97174
A20: 0.88 | B20: =$B$5*($A20+B$17)+$B$8 -> 156.24957 | C20: =$B$5*($A20+C$17)+$B$8 -> 159.15696 | D20: =$B$5*($A20+D$17)+$B$8 -> 162.06435 | E20: =$B$5*($A20+E$17)+$B$8 -> 164.97174 | F20: =$B$5*($A20+F$17)+$B$8 -> 167.87913
A21: 0.9 | B21: =$B$5*($A21+B$17)+$B$8 -> 159.15696 | C21: =$B$5*($A21+C$17)+$B$8 -> 162.06435 | D21: =$B$5*($A21+D$17)+$B$8 -> 164.97174 | E21: =$B$5*($A21+E$17)+$B$8 -> 167.87913 | F21: =$B$5*($A21+F$17)+$B$8 -> 170.78653
A22: 0.92 | B22: =$B$5*($A22+B$17)+$B$8 -> 162.06435 | C22: =$B$5*($A22+C$17)+$B$8 -> 164.97174 | D22: =$B$5*($A22+D$17)+$B$8 -> 167.87913 | E22: =$B$5*($A22+E$17)+$B$8 -> 170.78653 | F22: =$B$5*($A22+F$17)+$B$8 -> 173.69392
A23: 0.94 | B23: =$B$5*($A23+B$17)+$B$8 -> 164.97174 | C23: =$B$5*($A23+C$17)+$B$8 -> 167.87913 | D23: =$B$5*($A23+D$17)+$B$8 -> 170.78653 | E23: =$B$5*($A23+E$17)+$B$8 -> 173.69392 | F23: =$B$5*($A23+F$17)+$B$8 -> 176.60131
A25: GRR rows are inputs (blue); column headers step the base expansion rate by 2pp. 84% and 91% bracket the Benchmarkit and SaaS Capital medians.
A27: ARR growth vs base case
A28: GRR \ expansion | B28: =B17 -> 0.06945 | C28: =C17 -> 0.08945 | D28: =D17 -> 0.10945 | E28: =E17 -> 0.12945 | F28: =F17 -> 0.14945
A29: =A18 -> 0.84 | B29: =B18/$B$5-1 -> 0.03484348 | C29: =C18/$B$5-1 -> 0.05484348 | D29: =D18/$B$5-1 -> 0.07484348 | E29: =E18/$B$5-1 -> 0.09484348 | F29: =F18/$B$5-1 -> 0.11484348
A30: =A19 -> 0.86 | B30: =B19/$B$5-1 -> 0.05484348 | C30: =C19/$B$5-1 -> 0.07484348 | D30: =D19/$B$5-1 -> 0.09484348 | E30: =E19/$B$5-1 -> 0.11484348 | F30: =F19/$B$5-1 -> 0.13484348
A31: =A20 -> 0.88 | B31: =B20/$B$5-1 -> 0.07484348 | C31: =C20/$B$5-1 -> 0.09484348 | D31: =D20/$B$5-1 -> 0.11484348 | E31: =E20/$B$5-1 -> 0.13484348 | F31: =F20/$B$5-1 -> 0.15484348
A32: =A21 -> 0.9 | B32: =B21/$B$5-1 -> 0.09484348 | C32: =C21/$B$5-1 -> 0.11484348 | D32: =D21/$B$5-1 -> 0.13484348 | E32: =E21/$B$5-1 -> 0.15484348 | F32: =F21/$B$5-1 -> 0.17484348
A33: =A22 -> 0.92 | B33: =B22/$B$5-1 -> 0.11484348 | C33: =C22/$B$5-1 -> 0.13484348 | D33: =D22/$B$5-1 -> 0.15484348 | E33: =E22/$B$5-1 -> 0.17484348 | F33: =F22/$B$5-1 -> 0.19484348
A34: =A23 -> 0.94 | B34: =B23/$B$5-1 -> 0.13484348 | C34: =C23/$B$5-1 -> 0.15484348 | D34: =D23/$B$5-1 -> 0.17484348 | E34: =E23/$B$5-1 -> 0.19484348 | F34: =F23/$B$5-1 -> 0.21484348

Sheet Customer_ARR
A1: Account-Level ARR at July 2026 ($)
A2: Sorted by billed ARR, descending. Billed ARR = 12 x billed MRR.
A4: Customer | B4: Segment | C4: Industry | D4: Channel | E4: Pricing | F4: Term (months) | G4: Discount | H4: Months to renewal | I4: Billed ARR | J4: List ARR
A5: C00873 | B5: Enterprise | C5: Education | D5: Outbound | E5: usage | F5: 24 | G5: 0 | H5: 14 | I5: 833996.52 | J5: 833996.52
A6: C00435 | B6: Enterprise | C6: Retail | D6: Outbound | E6: hybrid | F6: 12 | G6: 0 | H6: 8 | I6: 541124.64 | J6: 541124.64
A7: C00720 | B7: Enterprise | C7: Manufacturing | D7: Partner | E7: usage | F7: 24 | G7: 0.25 | H7: 20 | I7: 521289.24 | J7: 695052.24
A8: C00127 | B8: Enterprise | C8: Education | D8: Outbound | E8: hybrid | F8: 12 | G8: 0.05 | H8: 12 | I8: 510670.56 | J8: 537548.04
A9: C01662 | B9: Enterprise | C9: Unknown | D9: Inbound | E9: usage | F9: 24 | G9: 0 | H9: 18 | I9: 503840.88 | J9: 503840.88
A10: C02577 | B10: Enterprise | C10: Education | D10: Inbound | E10: hybrid | F10: 12 | G10: 0 | H10: 1 | I10: 499972.92 | J10: 499972.92
A11: C00911 | B11: Enterprise | C11: Retail | D11: Outbound | E11: hybrid | F11: 24 | G11: 0 | H11: 19 | I11: 491146.08 | J11: 491146.08
A12: C02271 | B12: Enterprise | C12: Logistics | D12: Outbound | E12: usage | F12: 24 | G12: 0 | H12: 6 | I12: 436212 | J12: 436212
A13: C01211 | B13: Enterprise | C13: Manufacturing | D13: Outbound | E13: seat | F13: 12 | G13: 0 | H13: 4 | I13: 428389.92 | J13: 428389.92
A14: C02178 | B14: Enterprise | C14: Retail | D14: Outbound | E14: hybrid | F14: 12 | G14: 0 | H14: 4 | I14: 418928.52 | J14: 418928.52
A15: C00416 | B15: Enterprise | C15: Fintech | D15: Inbound | E15: seat | F15: 24 | G15: 0 | H15: 21 | I15: 409185.96 | J15: 409185.96
A16: C01234 | B16: Enterprise | C16: Healthcare | D16: Inbound | E16: usage | F16: 12 | G16: 0 | H16: 3 | I16: 407590.8 | J16: 407590.8
... A3509: C01602 | B3509: SMB | C3509: Fintech | D3509: Self-serve | E3509: seat | F3509: 1 | G3509: 0.35 | H3509: 1 | I3509: 2066.4 | J3509: 3179.04

Sheet Monthly_Bridge
A1: Monthly List-MRR Bridge ($)
A2: From sql/03_mrr_bridge.sql. Opening excludes nothing; new = first billed month.
A4: Month | B4: Opening | C4: New | D4: Expansion | E4: Contraction | F4: Churn | G4: Closing | H4: Roll-forward check | I4: Monthly GRR | J4: Monthly NRR
A5: 2022-02-01 | B5: 4816390.9 | C5: 88214.88 | D5: 69932.2 | E5: -27543.73 | F5: -21249.74 | G5: 4925744.5 | H5: =SUM(B5:F5)-G5 -> 0 | I5: =IF(B5=0,0,1+(E5+F5)/B5) -> 0.98986929 | J5: =IF(B5=0,0,1+(D5+E5+F5)/B5) -> 1.0043889
A6: 2022-03-01 | B6: 4925744.5 | C6: 92912.15 | D6: 77646.32 | E6: -34192.57 | F6: -31802.93 | G6: 5030307.5 | H6: =SUM(B6:F6)-G6 -> 0 | I6: =IF(B6=0,0,1+(E6+F6)/B6) -> 0.98660192 | J6: =IF(B6=0,0,1+(D6+E6+F6)/B6) -> 1.0023653
A7: 2022-04-01 | B7: 5030307.5 | C7: 75712.46 | D7: 88596.68 | E7: -27498.89 | F7: -40240.41 | G7: 5126877.3 | H7: =SUM(B7:F7)-G7 -> 0 | I7: =IF(B7=0,0,1+(E7+F7)/B7) -> 0.98653377 | J7: =IF(B7=0,0,1+(D7+E7+F7)/B7) -> 1.0041463
A8: 2022-05-01 | B8: 5126877.3 | C8: 65482.46 | D8: 78839.65 | E8: -33578.41 | F8: -37800.92 | G8: 5199820.1 | H8: =SUM(B8:F8)-G8 -> 0 | I8: =IF(B8=0,0,1+(E8+F8)/B8) -> 0.98607743 | J8: =IF(B8=0,0,1+(D8+E8+F8)/B8) -> 1.0014551
A9: 2022-06-01 | B9: 5199820.1 | C9: 101398.19 | D9: 67004.06 | E9: -25372.77 | F9: -37391.05 | G9: 5305458.5 | H9: =SUM(B9:F9)-G9 -> 0 | I9: =IF(B9=0,0,1+(E9+F9)/B9) -> 0.98792962 | J9: =IF(B9=0,0,1+(D9+E9+F9)/B9) -> 1.0008155
A10: 2022-07-01 | B10: 5305458.5 | C10: 100837.99 | D10: 69989.15 | E10: -30845.64 | F10: -40536.7 | G10: 5404903.3 | H10: =SUM(B10:F10)-G10 -> 0 | I10: =IF(B10=0,0,1+(E10+F10)/B10) -> 0.98654549 | J10: =IF(B10=0,0,1+(D10+E10+F10)/B10) -> 0.9997374
A11: 2022-08-01 | B11: 5404903.3 | C11: 105682.43 | D11: 72274.41 | E11: -28071.08 | F11: -17924.84 | G11: 5536864.3 | H11: =SUM(B11:F11)-G11 -> 0 | I11: =IF(B11=0,0,1+(E11+F11)/B11) -> 0.99148996 | J11: =IF(B11=0,0,1+(D11+E11+F11)/B11) -> 1.004862
A12: 2022-09-01 | B12: 5536864.3 | C12: 130784.23 | D12: 63771.32 | E12: -32362.02 | F12: -32174.12 | G12: 5666883.7 | H12: =SUM(B12:F12)-G12 -> 0 | I12: =IF(B12=0,0,1+(E12+F12)/B12) -> 0.98834428 | J12: =IF(B12=0,0,1+(D12+E12+F12)/B12) -> 0.99986187
A13: 2022-10-01 | B13: 5666883.7 | C13: 162579.19 | D13: 77451.16 | E13: -30899.12 | F13: -25660.55 | G13: 5850354.3 | H13: =SUM(B13:F13)-G13 -> 0 | I13: =IF(B13=0,0,1+(E13+F13)/B13) -> 0.99001926 | J13: =IF(B13=0,0,1+(D13+E13+F13)/B13) -> 1.0036866
A14: 2022-11-01 | B14: 5850354.3 | C14: 186160.64 | D14: 90665.84 | E14: -33813.96 | F14: -51437.29 | G14: 6041929.6 | H14: =SUM(B14:F14)-G14 -> 0 | I14: =IF(B14=0,0,1+(E14+F14)/B14) -> 0.98542802 | J14: =IF(B14=0,0,1+(D14+E14+F14)/B14) -> 1.0009255
A15: 2022-12-01 | B15: 6041929.6 | C15: 68604.14 | D15: 73426.19 | E15: -34403.18 | F15: -46792.77 | G15: 6102764 | H15: =SUM(B15:F15)-G15 -> 0 | I15: =IF(B15=0,0,1+(E15+F15)/B15) -> 0.98656126 | J15: =IF(B15=0,0,1+(D15+E15+F15)/B15) -> 0.99871403
A16: 2023-01-01 | B16: 6102764 | C16: 92319.57 | D16: 93593.62 | E16: -34810.67 | F16: -33937.37 | G16: 6219929.1 | H16: =SUM(B16:F16)-G16 -> 0 | I16: =IF(B16=0,0,1+(E16+F16)/B16) -> 0.98873493 | J16: =IF(B16=0,0,1+(D16+E16+F16)/B16) -> 1.0040712
... A58: 2026-07-01 | B58: 12114133 | C58: 149268.28 | D58: 135121.2 | E58: -83258.92 | F58: -99767.52 | G58: 12215496 | H58: =SUM(B58:F58)-G58 -> 0 | I58: =IF(B58=0,0,1+(E58+F58)/B58) -> 0.9848915 | J58: =IF(B58=0,0,1+(D58+E58+F58)/B58) -> 0.99604551
